WARNING 2024-01-22 17:34:22,741 django.request Bad Request: /api/instance/
WARNING 2024-01-22 18:00:52,225 django.request Bad Request: /api/instance/
WARNING 2024-01-22 18:01:21,233 django.request Bad Request: /api/instance/8782cbf4-f422-4045-955d-97f31fa04da2/redisgraph/check-module-loaded/
ERROR 2024-01-22 18:01:30,831 django.request Internal Server Error: /api/instance/8782cbf4-f422-4045-955d-97f31fa04da2/redistimeseries/module-info/
Traceback (most recent call last):
  File "/usr/local/lib/python3.11/site-packages/django/core/handlers/exception.py", line 56, in inner
    response = get_response(request)
               ^^^^^^^^^^^^^^^^^^^^^
  File "/usr/local/lib/python3.11/site-packages/django/core/handlers/base.py", line 197, in _get_response
    response = wrapped_callback(request, *callback_args, **callback_kwargs)
               ^^^^^^^^^^^^^^^^^^^^^^^^^^^^^^^^^^^^^^^^^^^^^^^^^^^^^^^^^^^^
  File "/usr/local/lib/python3.11/site-packages/django/views/decorators/csrf.py", line 55, in wrapped_view
    return view_func(*args, **kwargs)
           ^^^^^^^^^^^^^^^^^^^^^^^^^^
  File "/usr/local/lib/python3.11/site-packages/django/views/generic/base.py", line 103, in view
    return self.dispatch(request, *args, **kwargs)
           ^^^^^^^^^^^^^^^^^^^^^^^^^^^^^^^^^^^^^^^
  File "/usr/local/lib/python3.11/site-packages/rest_framework/views.py", line 509, in dispatch
    response = self.handle_exception(exc)
               ^^^^^^^^^^^^^^^^^^^^^^^^^^
  File "/usr/local/lib/python3.11/site-packages/rest_framework/views.py", line 469, in handle_exception
    self.raise_uncaught_exception(exc)
  File "/usr/local/lib/python3.11/site-packages/rest_framework/views.py", line 480, in raise_uncaught_exception
    raise exc
  File "/usr/local/lib/python3.11/site-packages/rest_framework/views.py", line 506, in dispatch
    response = handler(request, *args, **kwargs)
               ^^^^^^^^^^^^^^^^^^^^^^^^^^^^^^^^^
  File "/usr/local/lib/python3.11/site-packages/rest_framework/decorators.py", line 50, in handler
    return func(*args, **kwargs)
           ^^^^^^^^^^^^^^^^^^^^^
  File "./redisinsight/core/views/decorators.py", line 47, in _wrapped_view
  File "./redisinsight/utils/__init__.py", line 109, in _wrapped_view
  File "./redisinsight/utils/__init__.py", line 144, in _wrapped_view
  File "./redisinsight/core/services/licensing.py", line 325, in _wrapped_view
  File "./redisinsight/utils/__init__.py", line 199, in _wrapped_view
  File "./redisinsight/core/views/decorators.py", line 21, in wrapped_view
  File "./redisinsight/redistimeseries/decorators.py", line 39, in _wrapped_view
  File "./redisinsight/redistimeseries/utils.py", line 47, in get_redistimeseries_module_info
  File "/usr/local/lib/python3.11/site-packages/rediscluster/client.py", line 555, in execute_command
    return self._execute_command(*args, **kwargs)
           ^^^^^^^^^^^^^^^^^^^^^^^^^^^^^^^^^^^^^^
  File "/usr/local/lib/python3.11/site-packages/rediscluster/client.py", line 588, in _execute_command
    slot = self._determine_slot(*args)
           ^^^^^^^^^^^^^^^^^^^^^^^^^^^
  File "/usr/local/lib/python3.11/site-packages/rediscluster/client.py", line 481, in _determine_slot
    raise RedisClusterException("No way to dispatch this command to Redis Cluster. Missing key.")
rediscluster.exceptions.RedisClusterException: No way to dispatch this command to Redis Cluster. Missing key.
ERROR 2024-01-22 18:01:32,525 django.request Internal Server Error: /api/instance/8782cbf4-f422-4045-955d-97f31fa04da2/all-index/
Traceback (most recent call last):
  File "/usr/local/lib/python3.11/site-packages/django/core/handlers/exception.py", line 56, in inner
    response = get_response(request)
               ^^^^^^^^^^^^^^^^^^^^^
  File "/usr/local/lib/python3.11/site-packages/django/core/handlers/base.py", line 197, in _get_response
    response = wrapped_callback(request, *callback_args, **callback_kwargs)
               ^^^^^^^^^^^^^^^^^^^^^^^^^^^^^^^^^^^^^^^^^^^^^^^^^^^^^^^^^^^^
  File "/usr/local/lib/python3.11/site-packages/django/views/decorators/csrf.py", line 55, in wrapped_view
    return view_func(*args, **kwargs)
           ^^^^^^^^^^^^^^^^^^^^^^^^^^
  File "/usr/local/lib/python3.11/site-packages/django/views/generic/base.py", line 103, in view
    return self.dispatch(request, *args, **kwargs)
           ^^^^^^^^^^^^^^^^^^^^^^^^^^^^^^^^^^^^^^^
  File "/usr/local/lib/python3.11/site-packages/rest_framework/views.py", line 509, in dispatch
    response = self.handle_exception(exc)
               ^^^^^^^^^^^^^^^^^^^^^^^^^^
  File "/usr/local/lib/python3.11/site-packages/rest_framework/views.py", line 469, in handle_exception
    self.raise_uncaught_exception(exc)
  File "/usr/local/lib/python3.11/site-packages/rest_framework/views.py", line 480, in raise_uncaught_exception
    raise exc
  File "/usr/local/lib/python3.11/site-packages/rest_framework/views.py", line 506, in dispatch
    response = handler(request, *args, **kwargs)
               ^^^^^^^^^^^^^^^^^^^^^^^^^^^^^^^^^
  File "/usr/local/lib/python3.11/site-packages/rest_framework/decorators.py", line 50, in handler
    return func(*args, **kwargs)
           ^^^^^^^^^^^^^^^^^^^^^
  File "./redisinsight/core/views/decorators.py", line 47, in _wrapped_view
  File "./redisinsight/utils/__init__.py", line 109, in _wrapped_view
  File "./redisinsight/utils/__init__.py", line 144, in _wrapped_view
  File "./redisinsight/core/services/licensing.py", line 325, in _wrapped_view
  File "./redisinsight/core/services/access_control.py", line 198, in _wrapped_view
  File "./redisinsight/utils/__init__.py", line 199, in _wrapped_view
  File "./redisinsight/core/views/decorators.py", line 21, in wrapped_view
  File "./redisinsight/redisearch/decorators.py", line 35, in _wrapped_view
  File "./redisinsight/redisearch/views/__init__.py", line 12, in get_all_index
  File "./redisinsight/redisearch/services/api.py", line 271, in get_indices
  File "/usr/local/lib/python3.11/site-packages/rediscluster/client.py", line 555, in execute_command
    return self._execute_command(*args, **kwargs)
           ^^^^^^^^^^^^^^^^^^^^^^^^^^^^^^^^^^^^^^
  File "/usr/local/lib/python3.11/site-packages/rediscluster/client.py", line 588, in _execute_command
    slot = self._determine_slot(*args)
           ^^^^^^^^^^^^^^^^^^^^^^^^^^^
  File "/usr/local/lib/python3.11/site-packages/rediscluster/client.py", line 481, in _determine_slot
    raise RedisClusterException("No way to dispatch this command to Redis Cluster. Missing key.")
rediscluster.exceptions.RedisClusterException: No way to dispatch this command to Redis Cluster. Missing key.
WARNING 2024-01-22 18:01:32,529 django.request Bad Request: /api/instance/8782cbf4-f422-4045-955d-97f31fa04da2/check-redisearch-module-loaded/
